<?xml version="1.0"?>
<sdf version="1.10">
  <model name="diffbot">
    <pose>0 0 0.10 0 0 0</pose>
    <static>false</static>

    <link name="base_link">
      <inertial>
        <mass>5.0</mass>
        <inertia>
          <ixx>0.05</ixx><ixy>0</ixy><ixz>0</ixz>
          <iyy>0.08</iyy><iyz>0</iyz>
          <izz>0.10</izz>
        </inertia>
      </inertial>

      <collision name="base_collision">
        <pose>0 0 0.05 0 0 0</pose>
        <geometry>
          <box><size>0.30 0.20 0.10</size></box>
        </geometry>
      </collision>

      <visual name="base_visual">
        <pose>0 0 0.05 0 0 0</pose>
        <geometry>
          <box><size>0.30 0.20 0.10</size></box>
        </geometry>
      </visual>
    </link>

    <link name="left_wheel_link">
      <pose>0 0.11 0.05 0 0 0</pose>
      <inertial>
        <mass>0.3</mass>
        <inertia>
          <ixx>0.0005</ixx><ixy>0</ixy><ixz>0</ixz>
          <iyy>0.001</iyy><iyz>0</iyz>
          <izz>0.0005</izz>
        </inertia>
      </inertial>
      <collision name="left_wheel_collision">
        <geometry>
          <cylinder><radius>0.05</radius><length>0.02</length></cylinder>
        </geometry>
      </collision>
      <visual name="left_wheel_visual">
        <geometry>
          <cylinder><radius>0.05</radius><length>0.02</length></cylinder>
        </geometry>
      </visual>
    </link>

    <link name="right_wheel_link">
      <pose>0 -0.11 0.05 0 0 0</pose>
      <inertial>
        <mass>0.3</mass>
        <inertia>
          <ixx>0.0005</ixx><ixy>0</ixy><ixz>0</ixz>
          <iyy>0.001</iyy><iyz>0</iyz>
          <izz>0.0005</izz>
        </inertia>
      </inertial>
      <collision name="right_wheel_collision">
        <geometry>
          <cylinder><radius>0.05</radius><length>0.02</length></cylinder>
        </geometry>
      </collision>
      <visual name="right_wheel_visual">
        <geometry>
          <cylinder><radius>0.05</radius><length>0.02</length></cylinder>
        </geometry>
      </visual>
    </link>

    <joint name="left_wheel_joint" type="revolute">
      <parent>base_link</parent>
      <child>left_wheel_link</child>
      <axis>
        <xyz>0 1 0</xyz>
        <limit><lower>-1e16</lower><upper>1e16</upper></limit>
      </axis>
    </joint>

    <joint name="right_wheel_joint" type="revolute">
      <parent>base_link</parent>
      <child>right_wheel_link</child>
      <axis>
        <xyz>0 1 0</xyz>
        <limit><lower>-1e16</lower><upper>1e16</upper></limit>
      </axis>
    </joint>

    <link name="laser_link">
      <pose>0.12 0 0.15 0 0 0</pose>
      <inertial>
        <mass>0.1</mass>
        <inertia>
          <ixx>0.0001</ixx><ixy>0</ixy><ixz>0</ixz>
          <iyy>0.0001</iyy><iyz>0</iyz>
          <izz>0.0001</izz>
        </inertia>
      </inertial>

      <sensor name="lidar" type="lidar">
        <pose>0 0 0 0 0 0</pose>
        <update_rate>10</update_rate>
        <topic>/scan</topic>
        <lidar>
          <scan>
            <horizontal>
              <samples>360</samples>
              <resolution>1</resolution>
              <min_angle>-3.141592653589793</min_angle>
              <max_angle>3.141592653589793</max_angle>
            </horizontal>
          </scan>
          <range>
            <min>0.12</min>
            <max>6.0</max>
            <resolution>0.01</resolution>
          </range>
          <noise>
            <type>gaussian</type>
            <mean>0.0</mean>
            <stddev>0.005</stddev>
          </noise>
        </lidar>
      </sensor>
    </link>

    <joint name="laser_joint" type="fixed">
      <parent>base_link</parent>
      <child>laser_link</child>
    </joint>

    <plugin filename="gz-sim-diff-drive-system" name="gz::sim::systems::DiffDrive">
      <left_joint>left_wheel_joint</left_joint>
      <right_joint>right_wheel_joint</right_joint>
      <wheel_separation>0.22</wheel_separation>
      <wheel_radius>0.05</wheel_radius>
      <topic>/cmd_vel</topic>
      <odom_topic>/odom_raw</odom_topic>
      <tf_topic>/tf_raw</tf_topic>
      <frame_id>odom_raw</frame_id>
      <child_frame_id>base_link</child_frame_id>
      <odom_publish_frequency>50</odom_publish_frequency>
      <max_linear_acceleration>2.0</max_linear_acceleration>
      <max_angular_acceleration>4.0</max_angular_acceleration>
      <max_linear_velocity>1.0</max_linear_velocity>
      <max_angular_velocity>2.5</max_angular_velocity>
    </plugin>
  </model>
</sdf>
